Workbook
Name Fig_2: 'gasket table'!$J$20
Name Fig_3: 'gasket table'!$J$24
Name Fig_4: 'gasket table'!$J$28
Name Fig_5: 'gasket table'!$J$32
Name Fig_6: 'gasket table'!$J$36
Name Fig1a: 'gasket table'!$J$4
Name Fig1b: 'gasket table'!$J$8
Name Fig1c: 'gasket table'!$J$12
Name Fig1d: 'gasket table'!$J$16
Name myfig: INDIRECT('circular gasket'!$E$8)

Sheet content
A8: ASME BPVC Rules for Bolted Flange Connections with Gasket (linked to SOP-527)
A46: 0 | C46: 45628 | G46: First issue | P46: R&D - M. Di Somma | U46: QA/HSEM C.Delli Quadri - M.Tremolada | Z46: R&D Manager / M.Borghetti
A47: Rev. | C47: Date | G47: Description | P47: Prepared | U47: Checked | Z47: Approved
A48: Mod.498-0

Sheet circular gasket
B2: Gasket | H2: Legend
B3: ODgasket [mm] | C3: 100 | D3: (outside diameter) | H3: input data
B4: IDgasket [mm] | C4: 90 | D4: (inside diameter) | H4: descriptor
B5: p [bar] | C5: 100 | D5: (internal design pressure) | H5: calculated
B6: m [-] | C6: 3 | D6: (gasket factor) | H6: annotation
B7: y [MPa] | C7: 69 | D7: (gasket seating load)
B8: Gasket material | C8: Elastomers | E8: =VLOOKUP(C9,'gasket table'!T3:U11,2,FALSE) -> Fig1a
B9: Facing Sketch | C9: (1a)
B10: N [mm] | C10: 5 | D10: (gasket width)
B11: w [mm] | C11: 4 | D11: (width) | H11: =IF(C9<>"(6)",TRUE,FALSE) -> TRUE
B12: T [mm] | C12: 2 | D12: (gasket thickness) | H12: =IF(OR(C9="(1c)",C9="(1d)",C9="(2)",C9="(3)",C9="(6)"),TRUE,FALSE) -> FALSE
B13: G [mm] | C13: =IF(C14<=6,(C3+C4)/2,C3-2*C15) -> 95 | D13: (diameter at location of gasket load) | H13: =IF(OR(C9="(1c)",C9="(1d)"),TRUE,FALSE) -> FALSE
B14: b0 [mm] | C14: =VLOOKUP(C9,'gasket table'!T3:W11,VLOOKUP(C8,'gasket table'!Y3:Z10,2,FALSE),FALSE) -> 2.5 | D14: (basic gasket seating width)
B15: b [mm] | C15: =IF(C14<=6,C14,0.5*SQRT(C14)) -> 2.5 | D15: (effective gasket seating width)
B16: Wm1 [N] | C16: =PI()/4*C13^2*C5/10+2*C15*PI()*C13*C6*C5/10 -> 115649.88 | D16: (minimum required bolt load for operating conditions)
B17: Wm2 [N] | C17: =PI()*C13*C7*C15 -> 51482.85 | D17: (minimum required bolt load for gasket seating)
B18: W [N] | C18: =MAX(C16:C17) -> 115649.88 | D18: (required bolt load)
B20: Bolt
B21: (ratio of axial vs yield stress at serration) | C21: (number of bolt/stud) | D21: (bolt material yield stress) | E21: (resistant diameter of bolt/stud) | F21: (tightening force of bolt/stud)
B22: tightratio [-] | C22: nbolt [-] | D22: σyield [MPa] | E22: dres [mm] | F22: Fbolt [N]
B23: 0.7 | C23: 10 | D23: 724 | E23: 10 | F23: =B23*C23*D23*PI()/4*E23^2 -> 398039.79
B24: 0.7 | C24: 0 | D24: 724 | E24: 10 | F24: =B24*C24*D24*PI()/4*E24^2 -> 0
B25: 0.7 | C25: 0 | D25: 724 | E25: 10 | F25: =B25*C25*D25*PI()/4*E25^2 -> 0
B26: 0.7 | C26: 0 | D26: 724 | E26: 10 | F26: =B26*C26*D26*PI()/4*E26^2 -> 0
B27: 0.7 | C27: 0 | D27: 724 | E27: 10 | F27: =B27*C27*D27*PI()/4*E27^2 -> 0
B28: 0.7 | C28: 0 | D28: 724 | E28: 10 | F28: =B28*C28*D28*PI()/4*E28^2 -> 0
B29: 0.7 | C29: 0 | D29: 724 | E29: 10 | F29: =B29*C29*D29*PI()/4*E29^2 -> 0
B30: 0.7 | C30: 0 | D30: 724 | E30: 10 | F30: =B30*C30*D30*PI()/4*E30^2 -> 0 | H30: Warnings legend
B31: 0.7 | C31: 0 | D31: 724 | E31: 10 | F31: =B31*C31*D31*PI()/4*E31^2 -> 0 | H31: 0 | I31: not allowable
B32: 0.7 | C32: 0 | D32: 724 | E32: 10 | F32: =B32*C32*D32*PI()/4*E32^2 -> 0 | H32: 0.5 | I32: near to limit
E33: Ftot [N] | F33: =SUM(F23:F32) -> 398039.79 | H33: 1 | I33: allowable

Sheet not-circular gasket
B2: Gasket | H2: Legend
B3: Awet [mm2] | C3: 100 | D3: (effective wet area of the pump) | H3: input data
B4: Agasket [mm2] | C4: 90 | D4: (effective compressed area of the gasket) | H4: descriptor
B5: p [bar] | C5: 100 | D5: (internal design pressure) | H5: calculated
B6: m [-] | C6: 3 | D6: (gasket factor) | H6: annotation
B7: y [MPa] | C7: 69 | D7: (gasket seating load)
B8: Wm1 [N] | C8: =C5*C3+C5*C6*C4 -> 37000 | D8: (minimum required bolt load for operating conditions)
B9: Wm2 [N] | C9: =C4*C7/2 -> 3105 | D9: (minimum required bolt load for gasket seating)
B10: W [N] | C10: =MAX(C8:C9) -> 37000 | D10: (required bolt load)
B12: Bolt
B13: (ratio of axial vs yield stress at serration) | C13: (number of bolt/stud) | D13: (bolt material yield stress) | E13: (resistant diameter of bolt/stud) | F13: (tightening force of bolt/stud)
B14: tightratio [-] | C14: nbolt [-] | D14: σyield [MPa] | E14: dres [mm] | F14: Fbolt [N]
B15: 0.7 | C15: 10 | D15: 724 | E15: 5 | F15: =B15*C15*D15*PI()/4*E15^2 -> 99509.947
B16: 0.7 | C16: 0 | D16: 724 | E16: 10 | F16: =B16*C16*D16*PI()/4*E16^2 -> 0
B17: 0.7 | C17: 0 | D17: 724 | E17: 10 | F17: =B17*C17*D17*PI()/4*E17^2 -> 0
B18: 0.7 | C18: 0 | D18: 724 | E18: 10 | F18: =B18*C18*D18*PI()/4*E18^2 -> 0
B19: 0.7 | C19: 0 | D19: 724 | E19: 10 | F19: =B19*C19*D19*PI()/4*E19^2 -> 0
B20: 0.7 | C20: 0 | D20: 724 | E20: 10 | F20: =B20*C20*D20*PI()/4*E20^2 -> 0
B21: 0.7 | C21: 0 | D21: 724 | E21: 10 | F21: =B21*C21*D21*PI()/4*E21^2 -> 0
B22: 0.7 | C22: 0 | D22: 724 | E22: 10 | F22: =B22*C22*D22*PI()/4*E22^2 -> 0 | H22: Warnings legend
B23: 0.7 | C23: 0 | D23: 724 | E23: 10 | F23: =B23*C23*D23*PI()/4*E23^2 -> 0 | H23: 0 | I23: not allowable
B24: 0.7 | C24: 0 | D24: 724 | E24: 10 | F24: =B24*C24*D24*PI()/4*E24^2 -> 0 | H24: 0.5 | I24: near to limit
E25: Ftot [N] | F25: =SUM(F15:F24) -> 99509.947 | H25: 1 | I25: allowable

Sheet gasket table
B2: GASKET MATERIALS AND CONTACT FACINGS | I2: Facing Sketch (Exaggerated) | O2: Basic Gasket Seating Width bo
O3: Column I | Q3: Column II | T3: (1a) | U3: Fig1a | V3: ='circular gasket'!C10/2 -> 2.5 | W3: ='circular gasket'!C10/2 -> 2.5 | Y3: Elastomers | Z3: 4
B4: Gasket Material | C4: Gasket Factor m [-] | D4: Min Design Seating Stress y [MPa] | E4: Sketches | F4: Facing sketch | G4: Column | I4: (1a) | O4: N/2 | Q4: N/2 | T4: (1b) | U4: Fig1b | V4: ='circular gasket'!C10/2 -> 2.5 | W4: ='circular gasket'!C10/2 -> 2.5 | Y4: Vegetable fiber | Z4: 4
T5: (1c) | U5: Fig1c | V5: =MAX(('circular gasket'!C11+'circular gasket'!C12)/2,('circular gasket'!C11+'circular gasket'!C10)/4) -> 3 | W5: =MAX(('circular gasket'!C11+'circular gasket'!C12)/2,('circular gasket'!C11+'circular gasket'!C10)/4) -> 3 | Y5: Spiral-wound metal | Z5: 4
T6: (1d) | U6: Fig1d | V6: =MAX(('circular gasket'!C11+'circular gasket'!C12)/2,('circular gasket'!C11+'circular gasket'!C10)/4) -> 3 | W6: =MAX(('circular gasket'!C11+'circular gasket'!C12)/2,('circular gasket'!C11+'circular gasket'!C10)/4) -> 3 | Y6: Corrugated metal | Z6: 4
B7: Self-energizing types (o-rings, metallic, elastomer, other gasket types considered as self-sealing) | C7: 0 | D7: 0 | E7: … | F7: … | G7: … | T7: (2) | U7: Fig_2 | V7: =('circular gasket'!C11+'circular gasket'!C10)/4 -> 2.25 | W7: =('circular gasket'!C11+'circular gasket'!C10*3)/8 -> 2.375 | Y7: Flat metal | Z7: 4
I8: (1b) | T8: (3) | U8: Fig_3 | V8: ='circular gasket'!C10/4 -> 1.25 | W8: ='circular gasket'!C10/8*3 -> 1.875 | Y8: Grooved metal | Z8: 4
B9: Elastomers without fabric or high percent of asbestos fiber: | F9: (1a), (1b), (1c), (1d), (4), (5) | G9: II | T9: (4) | U9: Fig_4 | V9: ='circular gasket'!C10/8*3 -> 1.875 | W9: ='circular gasket'!C10/16*7 -> 2.1875 | Y9: Solid flat metal | Z9: 3
B10: • below 75A Shore Durometer | C10: 0.5 | D10: 0 | T10: (5) | U10: Fig_5 | V10: ='circular gasket'!C10/4 -> 1.25 | W10: ='circular gasket'!C10/8*3 -> 1.875 | Y10: Ring joint | Z10: 3
B11: • 75A or higher Shore Durometer | C11: 1 | D11: 1.4 | T11: (6) | U11: Fig_6 | V11: ='circular gasket'!C11/8 -> 0.5 | W11: =NA() -> #N/A
B12: Asbestos with suitable binder for operating conditions: | F12: (1a), (1b), (1c), (1d), (4), (5) | G12: II | I12: (1c) | N12: w≤N | O12: max((W+T)/2;(w+N)/4)) | Q12: max((W+T)/2;(w+N)/4))
B13: • 3.2 mm thick | C13: 2 | D13: 11
B14: • 1.6 mm thick | C14: 2.75 | D14: 26
B15: • 0.8 mm thick | C15: 3.5 | D15: 45
B16: Elastomers with cotton fabric insertion | C16: 1.25 | D16: 2.8 | F16: (1a), (1b), (1c), (1d), (4), (5) | G16: II | I16: (1d) | N16: w≤N see note 1
B19: Elastomers with asbestos fabric insertion (with or without wire reinforcement): | F19: (1a), (1b), (1c), (1d), (4), (5) | G19: II
I20: (2) | N20: w≤N/2 | O20: (w+N)/4 | Q20: (w+3N)/8
B21: • 3-ply | C21: 2.25 | D21: 15
B24: • 2-ply | C24: 2.5 | D24: 20 | I24: (3) | N24: w≤N/2 | O24: N/4 | Q24: 3N/8
B27: • 1-ply | C27: 2.75 | D27: 26
I28: (4) | O28: 3N/8 | Q28: 7N/16
B30: Vegetable fiber | C30: 1.75 | D30: 7.6 | F30: (1a), (1b), (1c), (1d), (4), (5) | G30: II
I32: (5) | O32: N/4 | Q32: 3N/8
B33: Spiral-wound metal, asbestos filled: | F33: (1a), (1b) | G33: II
B34: • carbon | C34: 2.5 | D34: 69
B35: • stainless, monel, and nickel-base alloy | C35: 3 | D35: 69
B36: Corrugated metal, asbestos inserted, or corrugated metal, acketed asbestos filled: | F36: (1a), (1b) | G36: II | I36: (6) | O36: w/8 | Q36: …
B38: • soft aluminium | C38: 2.5 | D38: 20
B39: • soft copper or brass | C39: 2.75 | D39: 26
B40: • iron or soft steel | C40: 3 | D40: 31 | I40: Effective Gasket Seating Width b
B41: • monel or 4%–6% chrome | C41: 3.25 | D41: 38
B42: • stainless steels and nickel-base alloys | C42: 3.5 | D42: 45
B43: Corrugated metal: | F43: (1a), (1b), (1c), (1d) | G43: II
B44: • soft aluminium | C44: 2.75 | D44: 26
B45: • soft copper or brass | C45: 3 | D45: 31
B46: • iron or soft steel | C46: 3.25 | D46: 38
B47: • monel or 4%–6% chrome | C47: 3.5 | D47: 45
B48: • stainless steels and nickel-base alloys | C48: 3.75 | D48: 52
B49: Flat metal, jacketed asbestos filled: | F49: (1a), (1b), (1c), (1d), (2) | G49: II
B50: • soft aluminium | C50: 3.25 | D50: 38
...
